Workbook

Sheet 🗺️ Ba Gua Automático
A1: 🗺️ BA GUA AUTOMÁTICO — Chapéu Preto
A3: ℹ️ Selecione a posição da Porta de Entrada. O Ba Gua se ajusta automaticamente.
A4: 🚪 Porta de Entrada: | C4: Centro-Frente | F4: ← Selecione aqui
N6: [TABELA INTERNA — NÃO EDITAR] | V6: =INDEX(O7:W9,MATCH($C$4,N7:N9,0),1) | W6: =INDEX(O7:W9,MATCH($C$4,N7:N9,0),2) | X6: =INDEX(O7:W9,MATCH($C$4,N7:N9,0),3) | Y6: =INDEX(O7:W9,MATCH($C$4,N7:N9,0),4) | Z6: =INDEX(O7:W9,MATCH($C$4,N7:N9,0),5) | AA6: =INDEX(O7:W9,MATCH($C$4,N7:N9,0),6) | AB6: =INDEX(O7:W9,MATCH($C$4,N7:N9,0),7) | AC6: =INDEX(O7:W9,MATCH($C$4,N7:N9,0),8) | AD6: =INDEX(O7:W9,MATCH($C$4,N7:N9,0),9)
A7: 🏠 MAPA BA GUA — Atualiza conforme a Porta de Entrada | N7: Centro-Frente | O7: Prosperidade | P7: Fama | Q7: Relacionamentos | R7: Família | S7: Saúde | T7: Criatividade | U7: Conhecimento | V7: Carreira | W7: Ajudantes
A8: ⬆️ FUNDO DA CASA | N8: Esquerda-Frente | O8: Fama | P8: Relacionamentos | Q8: Criatividade | R8: Prosperidade | S8: Saúde | T8: Ajudantes | U8: Família | V8: Conhecimento | W8: Carreira
A9: =V6 | E9: =W6 | I9: =X6 | N9: Direita-Frente | O9: Conhecimento | P9: Prosperidade | Q9: Fama | R9: Carreira | S9: Saúde | T9: Relacionamentos | U9: Ajudantes | V9: Criatividade | W9: Família
A10: ← Digite o cômodo | E10: ← Digite o cômodo | I10: ← Digite o cômodo
A11: Área Faltando? Não | E11: Área Faltando? Não | I11: Área Faltando? Não
A13: =Y6 | E13: =Z6 | I13: =AA6
A14: ← Digite o cômodo | E14: ← Digite o cômodo | I14: ← Digite o cômodo
A15: Área Faltando? Não | E15: Área Faltando? Não | I15: Área Faltando? Não
A17: =AB6 | E17: =AC6 | I17: =AD6
A18: ← Digite o cômodo | E18: ← Digite o cômodo | I18: ← Digite o cômodo
A19: Área Faltando? Não | E19: Área Faltando? Não | I19: Área Faltando? Não
A20: ⬇️ FRENTE DA CASA — PORTA DE ENTRADA

Sheet 👤 Cliente
A1: 👤 CADASTRO DO CLIENTE
A3: 📌 DADOS DO CONSULTOR
A4: Nome do Cliente: | D4: CPF / Doc:
A5: Nome do Consultor: | D5: Registro:
A6: Empresa / Studio: | D6: WhatsApp:
A7: E-mail: | D7: Data da Consulta:
A9: 🏠 DADOS DO IMÓVEL
A10: Endereço:
A11: Tipo de Imóvel:
A12: Metragem (m²):
A13: Nº de Cômodos:
A14: Andar:
A15: Porta voltada para:
A17: 👨‍👩‍👧 COMPOSIÇÃO FAMILIAR
A18: Nome | B18: Relação | C18: Idade | D18: Quarto/Área | E18: Intenção Principal | F18: Setor Relevante
A26: 🎯 INTENÇÕES POR ÁREA DE VIDA
A27: Área de Vida | B27: Prior.(1-9) | C27: Situação Atual | E27: Desejo / Intenção
A28: Prosperidade / Finanças
A29: Saúde / Bem-estar
A30: Relacionamentos / Amor
A31: Carreira / Profissional
A32: Família / Harmonia
A33: Criatividade / Projetos
A34: Fama / Reconhecimento
A35: Conhecimento / Espiritualidade
A36: Ajudantes / Viagens

Sheet 🔍 Diagnóstico
A1: 🔍 DIAGNÓSTICO ENERGÉTICO — Checklist por Setor
A3: LEGENDA → 3 = Sim/Bom | 2 = Parcial | 1 = Não/Ruim | 0 = Ausente/Crítico
A4: 📝 CLIQUE NA CÉLULA AZUL e selecione: 0 = Crítico ❌ | 1 = Ruim ⚠️ | 2 = Parcial 🔶 | 3 = Bom ✅ (Células azuis = editáveis)
A5: Setor Ba Gua
A6: 🔴 PROSPERIDADE
A7: Cômodo(s): | B7: Suíte 1 + Closet + Terraço Técnico
A8: Prosperidade | B8: Suíte 1 + Closet + Terraço Técnico | C8: Tem boa iluminação natural e artificial? | D8: 3 | E8: 3 | F8: 3 | G8: 3 | H8: 3 | I8: 3 | J8: 3 | K8: 3
A9: Prosperidade | B9: Suíte 1 + Closet + Terraço Técnico | C9: Planta viva e saudável presente? | D9: 3 | E9: 3 | F9: 3 | G9: 3 | H9: 3 | I9: 3 | J9: 3 | K9: 3
A10: Prosperidade | B10: Suíte 1 + Closet + Terraço Técnico | C10: Espaço organizado, sem acúmulo? | D10: 3 | E10: 3 | F10: 3 | G10: 3 | H10: 3 | I10: 3 | J10: 3 | K10: 3
A11: Prosperidade | B11: Suíte 1 + Closet + Terraço Técnico | C11: Chi circula livremente (sem bloqueios)? | D11: 3 | E11: 3 | F11: 3 | G11: 3 | H11: 3 | I11: 3 | J11: 3 | K11: 3
A12: Prosperidade | B12: Suíte 1 + Closet + Terraço Técnico | C12: Cor dominante compatível com o setor? | D12: 3 | E12: 3 | F12: 3 | G12: 3 | H12: 3 | I12: 3 | J12: 3 | K12: 3
A13: Prosperidade | B13: Suíte 1 + Closet + Terraço Técnico | C13: Espelhos posicionados corretamente? | D13: 3 | E13: 3 | F13: 3 | G13: 3 | H13: 3 | I13: 3 | J13: 3 | K13: 3
A14: Prosperidade | B14: Suíte 1 + Closet + Terraço Técnico | C14: Porta abre 100%? Janelas funcionam? | D14: 3 | E14: 3 | F14: 3 | G14: 3 | H14: 3 | I14: 3 | J14: 3 | K14: 3
A15: Prosperidade | B15: Suíte 1 + Closet + Terraço Técnico | D15: 3 | E15: 3 | F15: 3 | G15: 3 | H15: 3 | I15: 3 | J15: 3 | K15: 3
A16: TOTAL: | L16: =SUM(D7:K14) | M16: 24 | N16: =IF(L15>0,L15/M15,0)
A18: 🔥 FAMA
A19: Cômodo(s): | B19: Suíte Master
A20: Fama | B20: Suíte Master | C20: Tem boa iluminação natural e artificial? | D20: 3 | E20: 3 | F20: 3 | G20: 3 | H20: 3 | I20: 3 | J20: 3 | K20: 3
A21: Fama | B21: Suíte Master | C21: Planta viva e saudável presente? | D21: 3 | E21: 3 | F21: 3 | G21: 3 | H21: 3 | I21: 3 | J21: 3 | K21: 3
A22: Fama | B22: Suíte Master | C22: Espaço organizado, sem acúmulo? | D22: 3 | E22: 3 | F22: 3 | G22: 3 | H22: 3 | I22: 3 | J22: 3 | K22: 3
A23: Fama | B23: Suíte Master | C23: Chi circula livremente (sem bloqueios)? | D23: 3 | E23: 3 | F23: 3 | G23: 3 | H23: 3 | I23: 3 | J23: 3 | K23: 3
A24: Fama | B24: Suíte Master | C24: Cor dominante compatível com o setor? | D24: 3 | E24: 3 | F24: 3 | G24: 3 | H24: 3 | I24: 3 | J24: 3 | K24: 3
A25: Fama | B25: Suíte Master | C25: Espelhos posicionados corretamente? | D25: 3 | E25: 3 | F25: 3 | G25: 3 | H25: 3 | I25: 3 | J25: 3 | K25: 3
A26: Fama | B26: Suíte Master | C26: Porta abre 100%? Janelas funcionam? | D26: 3 | E26: 3 | F26: 3 | G26: 3 | H26: 3 | I26: 3 | J26: 3 | K26: 3
A27: Fama | B27: Suíte Master | D27: 3 | E27: 3 | F27: 3 | G27: 3 | H27: 3 | I27: 3 | J27: 3 | K27: 3
A28: TOTAL: | L28: =SUM(D19:K26) | M28: 24 | N28: =IF(L27>0,L27/M27,0)
A30: 💜 RELACIONAMENTOS
A31: Cômodo(s): | B31: Suíte 2 + Home Office
A32: Relacionamentos | B32: Suíte 2 + Home Office | C32: Tem boa iluminação natural e artificial? | D32: 3 | E32: 3 | F32: 3 | G32: 3 | H32: 3 | I32: 3 | J32: 3 | K32: 3
A33: Relacionamentos | B33: Suíte 2 + Home Office | C33: Planta viva e saudável presente? | D33: 3 | E33: 3 | F33: 3 | G33: 3 | H33: 3 | I33: 3 | J33: 3 | K33: 3
A34: Relacionamentos | B34: Suíte 2 + Home Office | C34: Espaço organizado, sem acúmulo? | D34: 3 | E34: 3 | F34: 3 | G34: 3 | H34: 3 | I34: 3 | J34: 3 | K34: 3
A35: Relacionamentos | B35: Suíte 2 + Home Office | C35: Chi circula livremente (sem bloqueios)? | D35: 3 | E35: 3 | F35: 3 | G35: 3 | H35: 3 | I35: 3 | J35: 3 | K35: 3
A36: Relacionamentos | B36: Suíte 2 + Home Office | C36: Cor dominante compatível com o setor? | D36: 3 | E36: 3 | F36: 3 | G36: 3 | H36: 3 | I36: 3 | J36: 3 | K36: 3
A37: Relacionamentos | B37: Suíte 2 + Home Office | C37: Espelhos posicionados corretamente? | D37: 3 | E37: 3 | F37: 3 | G37: 3 | H37: 3 | I37: 3 | J37: 3 | K37: 3
A38: Relacionamentos | B38: Suíte 2 + Home Office | C38: Porta abre 100%? Janelas funcionam? | D38: 3 | E38: 3 | F38: 3 | G38: 3 | H38: 3 | I38: 3 | J38: 3 | K38: 3
A39: Relacionamentos | B39: Suíte 2 + Home Office | D39: 3 | E39: 3 | F39: 3 | G39: 3 | H39: 3 | I39: 3 | J39: 3 | K39: 3
A40: TOTAL: | L40: =SUM(D31:K38) | M40: 24 | N40: =IF(L39>0,L39/M39,0)
A42: 🌿 FAMÍLIA
A43: Cômodo(s): | B43: Lavanderia + Dorm. Serviço
A44: Família | B44: Lavanderia + Dorm. Serviço | C44: Tem boa iluminação natural e artificial? | D44: 3 | E44: 3 | F44: 3 | G44: 3 | H44: 3 | I44: 3 | J44: 3 | K44: 3
...

Sheet 📊 Score Energético
A1: 📊 SCORE ENERGÉTICO — Semáforo Automático
A3: 🚦 LEGENDA
A4: 🟢 80–100% | B4: EXCELENTE — Manutenção apenas
A5: 🟡 60–79% | B5: BOM — Melhorias pontuais
A6: 🟠 40–59% | B6: ATENÇÃO — Intervenção necessária
A7: 🔴 0–39% | B7: CRÍTICO — Prioridade máxima
A9: 📈 SCORES — ALIMENTADOS AUTOMATICAMENTE DO DIAGNÓSTICO
A10: Setor | B10: Elemento | C10: Cor Ideal | D10: Score | E10: Máx | F10: % Saúde | G10: Status 🚦 | H10: Prioridade
A11: 🔴 Prosperidade | B11: Madeira + Metal | C11: Roxo / Dourado | D11: ='🔍 Diagnóstico'!L15 | E11: ='🔍 Diagnóstico'!M15 | F11: =IF(E11>0,D11/E11,0) | G11: =IF(F11>=0.8,"🟢 Excelente",IF(F11>=0.6,"🟡 Bom",IF(F11>=0.4,"🟠 Atenção","🔴 Crítico"))) | H11: =IF(F11<0.4,"1️⃣ URGENTE",IF(F11<0.6,"2️⃣ ALTA",IF(F11<0.8,"3️⃣ MÉDIA","4️⃣ BAIXA")))
A12: 🔥 Fama | B12: Fogo | C12: Vermelho / Coral | D12: ='🔍 Diagnóstico'!L27 | E12: ='🔍 Diagnóstico'!M27 | F12: =IF(E12>0,D12/E12,0) | G12: =IF(F12>=0.8,"🟢 Excelente",IF(F12>=0.6,"🟡 Bom",IF(F12>=0.4,"🟠 Atenção","🔴 Crítico"))) | H12: =IF(F12<0.4,"1️⃣ URGENTE",IF(F12<0.6,"2️⃣ ALTA",IF(F12<0.8,"3️⃣ MÉDIA","4️⃣ BAIXA")))
A13: 💜 Relacionamentos | B13: Terra | C13: Rosa / Terracota | D13: ='🔍 Diagnóstico'!L39 | E13: ='🔍 Diagnóstico'!M39 | F13: =IF(E13>0,D13/E13,0) | G13: =IF(F13>=0.8,"🟢 Excelente",IF(F13>=0.6,"🟡 Bom",IF(F13>=0.4,"🟠 Atenção","🔴 Crítico"))) | H13: =IF(F13<0.4,"1️⃣ URGENTE",IF(F13<0.6,"2️⃣ ALTA",IF(F13<0.8,"3️⃣ MÉDIA","4️⃣ BAIXA")))
A14: 🌿 Família | B14: Madeira | C14: Verde | D14: ='🔍 Diagnóstico'!L51 | E14: ='🔍 Diagnóstico'!M51 | F14: =IF(E14>0,D14/E14,0) | G14: =IF(F14>=0.8,"🟢 Excelente",IF(F14>=0.6,"🟡 Bom",IF(F14>=0.4,"🟠 Atenção","🔴 Crítico"))) | H14: =IF(F14<0.4,"1️⃣ URGENTE",IF(F14<0.6,"2️⃣ ALTA",IF(F14<0.8,"3️⃣ MÉDIA","4️⃣ BAIXA")))
A15: 🟡 Saúde | B15: Terra | C15: Amarelo / Bege | D15: ='🔍 Diagnóstico'!L63 | E15: ='🔍 Diagnóstico'!M63 | F15: =IF(E15>0,D15/E15,0) | G15: =IF(F15>=0.8,"🟢 Excelente",IF(F15>=0.6,"🟡 Bom",IF(F15>=0.4,"🟠 Atenção","🔴 Crítico"))) | H15: =IF(F15<0.4,"1️⃣ URGENTE",IF(F15<0.6,"2️⃣ ALTA",IF(F15<0.8,"3️⃣ MÉDIA","4️⃣ BAIXA")))
A16: ⭕ Criatividade | B16: Metal | C16: Branco / Dourado | D16: ='🔍 Diagnóstico'!L75 | E16: ='🔍 Diagnóstico'!M75 | F16: =IF(E16>0,D16/E16,0) | G16: =IF(F16>=0.8,"🟢 Excelente",IF(F16>=0.6,"🟡 Bom",IF(F16>=0.4,"🟠 Atenção","🔴 Crítico"))) | H16: =IF(F16<0.4,"1️⃣ URGENTE",IF(F16<0.6,"2️⃣ ALTA",IF(F16<0.8,"3️⃣ MÉDIA","4️⃣ BAIXA")))
A17: 📚 Conhecimento | B17: Terra + Água | C17: Azul-verde escuro | D17: ='🔍 Diagnóstico'!L87 | E17: ='🔍 Diagnóstico'!M87 | F17: =IF(E17>0,D17/E17,0) | G17: =IF(F17>=0.8,"🟢 Excelente",IF(F17>=0.6,"🟡 Bom",IF(F17>=0.4,"🟠 Atenção","🔴 Crítico"))) | H17: =IF(F17<0.4,"1️⃣ URGENTE",IF(F17<0.6,"2️⃣ ALTA",IF(F17<0.8,"3️⃣ MÉDIA","4️⃣ BAIXA")))
A18: 🔵 Carreira | B18: Água | C18: Azul-escuro | D18: ='🔍 Diagnóstico'!L99 | E18: ='🔍 Diagnóstico'!M99 | F18: =IF(E18>0,D18/E18,0) | G18: =IF(F18>=0.8,"🟢 Excelente",IF(F18>=0.6,"🟡 Bom",IF(F18>=0.4,"🟠 Atenção","🔴 Crítico"))) | H18: =IF(F18<0.4,"1️⃣ URGENTE",IF(F18<0.6,"2️⃣ ALTA",IF(F18<0.8,"3️⃣ MÉDIA","4️⃣ BAIXA")))
A19: 🤝 Ajudantes | B19: Metal + Água | C19: Cinza / Dourado | D19: ='🔍 Diagnóstico'!L111 | E19: ='🔍 Diagnóstico'!M111 | F19: =IF(E19>0,D19/E19,0) | G19: =IF(F19>=0.8,"🟢 Excelente",IF(F19>=0.6,"🟡 Bom",IF(F19>=0.4,"🟠 Atenção","🔴 Crítico"))) | H19: =IF(F19<0.4,"1️⃣ URGENTE",IF(F19<0.6,"2️⃣ ALTA",IF(F19<0.8,"3️⃣ MÉDIA","4️⃣ BAIXA")))

Sheet 🕸️ Mapa Radar
A1: 🕸️ MAPA RADAR ENERGÉTICO — Visão Geral dos 9 Setores
A3: Gráfico atualiza automaticamente conforme o Diagnóstico é preenchido.
A5: DADOS DO RADAR — Atualizados Automaticamente
A6: Setor | B6: % Saúde | C6: Status
A7: 🔴 Prosperidade | B7: ='📊 Score Energético'!F11 | C7: ='📊 Score Energético'!G11
A8: 🔥 Fama | B8: ='📊 Score Energético'!F12 | C8: ='📊 Score Energético'!G12
A9: 💜 Relacionamentos | B9: ='📊 Score Energético'!F13 | C9: ='📊 Score Energético'!G13
A10: 🌿 Família | B10: ='📊 Score Energético'!F14 | C10: ='📊 Score Energético'!G14
A11: 🟡 Saúde | B11: ='📊 Score Energético'!F15 | C11: ='📊 Score Energético'!G15
A12: ⭕ Criatividade | B12: ='📊 Score Energético'!F16 | C12: ='📊 Score Energético'!G16
A13: 📚 Conhecimento | B13: ='📊 Score Energético'!F17 | C13: ='📊 Score Energético'!G17
A14: 🔵 Carreira | B14: ='📊 Score Energético'!F18 | C14: ='📊 Score Energético'!G18
A15: 🤝 Ajudantes | B15: ='📊 Score Energético'!F19 | C15: ='📊 Score Energético'!G19

Sheet 💊 Prescrições
A1: 💊 PRESCRIÇÕES — Auto-priorizadas pelo Score do Diagnóstico
L2: [AUXILIAR — NÃO EDITAR]
A3: ✅ As prescrições são ordenadas automaticamente do setor mais crítico para o menos crítico. | L3: Prosperidade | M3: ='📊 Score Energético'!F11
L4: Fama | M4: ='📊 Score Energético'!F12
A5: PLANO DE ATIVAÇÕES — ORDEM DE PRIORIDADE AUTOMÁTICA | L5: Relacionamentos | M5: ='📊 Score Energético'!F13
A6: Prior. | B6: Setor | C6: % Saúde | D6: Problema Identificado | E6: Objeto / Ativação | F6: Mantra dos Três Segredos | H6: Visualização | I6: Fase Lunar | J6: Concluído? | L6: Família | M6: ='📊 Score Energético'!F14
A7: #1 | B7: =IFERROR(INDEX(L3:L11,MATCH(SMALL(M3:M11,1),M3:M11,0)),"—") | C7: =IFERROR(SMALL(M3:M11,1),"") | D7: ← preencher conforme setor | E7: ← preencher conforme setor | F7: ← preencher conforme setor | H7: ← preencher conforme setor | I7: ← preencher conforme setor | J7: ← preencher conforme setor | L7: Saúde | M7: ='📊 Score Energético'!F15
A8: #2 | B8: =IFERROR(INDEX(L3:L11,MATCH(SMALL(M3:M11,2),M3:M11,0)),"—") | C8: =IFERROR(SMALL(M3:M11,2),"") | D8: ← preencher conforme setor | E8: ← preencher conforme setor | F8: ← preencher conforme setor | H8: ← preencher conforme setor | I8: ← preencher conforme setor | J8: ← preencher conforme setor | L8: Criatividade | M8: ='📊 Score Energético'!F16
A9: #3 | B9: =IFERROR(INDEX(L3:L11,MATCH(SMALL(M3:M11,3),M3:M11,0)),"—") | C9: =IFERROR(SMALL(M3:M11,3),"") | D9: ← preencher conforme setor | E9: ← preencher conforme setor | F9: ← preencher conforme setor | H9: ← preencher conforme setor | I9: ← preencher conforme setor | J9: ← preencher conforme setor | L9: Conhecimento | M9: ='📊 Score Energético'!F17
A10: #4 | B10: =IFERROR(INDEX(L3:L11,MATCH(SMALL(M3:M11,4),M3:M11,0)),"—") | C10: =IFERROR(SMALL(M3:M11,4),"") | D10: ← preencher conforme setor | E10: ← preencher conforme setor | F10: ← preencher conforme setor | H10: ← preencher conforme setor | I10: ← preencher conforme setor | J10: ← preencher conforme setor | L10: Carreira | M10: ='📊 Score Energético'!F18
A11: #5 | B11: =IFERROR(INDEX(L3:L11,MATCH(SMALL(M3:M11,5),M3:M11,0)),"—") | C11: =IFERROR(SMALL(M3:M11,5),"") | D11: ← preencher conforme setor | E11: ← preencher conforme setor | F11: ← preencher conforme setor | H11: ← preencher conforme setor | I11: ← preencher conforme setor | J11: ← preencher conforme setor | L11: Ajudantes | M11: ='📊 Score Energético'!F19
A12: #6 | B12: =IFERROR(INDEX(L3:L11,MATCH(SMALL(M3:M11,6),M3:M11,0)),"—") | C12: =IFERROR(SMALL(M3:M11,6),"") | D12: ← preencher conforme setor | E12: ← preencher conforme setor | F12: ← preencher conforme setor | H12: ← preencher conforme setor | I12: ← preencher conforme setor | J12: ← preencher conforme setor
A13: #7 | B13: =IFERROR(INDEX(L3:L11,MATCH(SMALL(M3:M11,7),M3:M11,0)),"—") | C13: =IFERROR(SMALL(M3:M11,7),"") | D13: ← preencher conforme setor | E13: ← preencher conforme setor | F13: ← preencher conforme setor | H13: ← preencher conforme setor | I13: ← preencher conforme setor | J13: ← preencher conforme setor
A14: #8 | B14: =IFERROR(INDEX(L3:L11,MATCH(SMALL(M3:M11,8),M3:M11,0)),"—") | C14: =IFERROR(SMALL(M3:M11,8),"") | D14: ← preencher conforme setor | E14: ← preencher conforme setor | F14: ← preencher conforme setor | H14: ← preencher conforme setor | I14: ← preencher conforme setor | J14: ← preencher conforme setor
A15: #9 | B15: =IFERROR(INDEX(L3:L11,MATCH(SMALL(M3:M11,9),M3:M11,0)),"—") | C15: =IFERROR(SMALL(M3:M11,9),"") | D15: ← preencher conforme setor | E15: ← preencher conforme setor | F15: ← preencher conforme setor | H15: ← preencher conforme setor | I15: ← preencher conforme setor | J15: ← preencher conforme setor
A17: 📚 BASE DE PRESCRIÇÕES — Copie os textos conforme o setor identificado
A18: Setor | B18: Problema | C18: Ativação / Objeto | E18: Mantra | G18: Visualização | I18: Fase Lunar | J18: Notas
A19: Prosperidade | B19: Área técnica/vazia no setor | C19: Planta robusta + luz p/ cima + objeto dourado no closet | E19: "Esta planta cresce e floresce, assim como a abundância flui para minha vida de forma constante, fácil e merecida" | G19: Corrente de água limpa trazendo recursos e oportunidades em abundância | I19: 🌒 Crescente
A20: Fama | B20: Setor sem elemento fogo ativo | C20: Iluminação forte no teto + obra em tons de fogo + diplomas em molduras | E20: "Sou reconhecido(a) pelo melhor que tenho a oferecer. Meu nome é lembrado com respeito e admiração" | G20: Farol irradiando energia que atrai reconhecimento genuíno | I20: 🌕 Cheia
A21: Relacionamentos | B21: Falta de ativação de pares | C21: Objetos em pares simétricos + cristal quartzo rosa + luz quente | E21: "Atraio relacionamentos saudáveis, recíprocos e enriquecedores. Sou digno(a) de amor pleno" | G21: Dois seres que se completam, campo de amor e segurança envolvendo o quarto | I21: 🌕 Cheia
A22: Família | B22: Área de serviço no setor familiar | C22: Planta folha larga + foto de família + reorganização profunda | E22: "Nossas raízes são profundas, nossos laços são fortes. Harmonia e apoio fluem entre todos nós" | G22: Família reunida, laços como raízes de árvore grande e sólida | I22: 🌑 Nova
A23: Saúde | B23: Corredor acelera o chi | C23: Tapete natural no corredor + cristal citrino + iluminação equilibrada | E23: "Este tapete ancora minha saúde e de todos que vivem neste lar. Nossa vitalidade é forte e renovada" | G23: Moradores caminhando com leveza, chi fluindo suavemente como água pela terra | I23: 🌑 Nova
A24: Criatividade | B24: Terraço com energia dispersa | C24: Flores em vasos + elemento circular no living + fruteira na mesa | E24: "O círculo representa criação sem fim. A criatividade flui, as ideias surgem com facilidade e alegria" | G24: Espaço vivo, conversas que inspiram, projetos nascendo espontaneamente | I24: 🌒 Crescente
A25: Conhecimento | B25: Falta de elemento terra e água | C25: Cristal azul ou verde + livros organizados + luz suave | E25: "Este espaço nutre minha mente e minha alma. O conhecimento flui e me transforma continuamente" | G25: Mente clara e aberta, absorvendo sabedoria com facilidade e prazer | I25: 🌑 Nova
A26: Carreira | B26: Entrada sem ativação adequada | C26: Espelho lateral + tapete de qualidade + iluminação forte na entrada | E26: "Este espelho acolhe e amplifica as oportunidades. Minha carreira se expande, meu propósito é claro" | G26: Chegando em casa após grande conquista profissional, expressão de satisfação plena | I26: 🌒 Crescente
A27: Ajudantes | B27: Área de acesso sem ativação | C27: Elemento metálico + luz na entrada de serviço + organização | E27: "Atraio as pessoas certas, no momento certo. Sou apoiado(a) por parceiros, mentores e recursos" | G27: Rede de apoio sólida chegando quando mais preciso, portas se abrindo naturalmente | I27: 🌒 Crescente

Sheet 📄 Relatório
A1: FENG SHUI CHAPÉU PRETO Relatório de Diagnóstico e Plano de Ativação
A4: ✨ Que este lar seja um portal de prosperidade, saúde, amor e realização ✨
A5: ✅ Nome do cliente, consultor, data e endereço são preenchidos AUTOMATICAMENTE da aba 👤 Cliente
A7: 📋 DADOS DA CONSULTA
A8: Cliente: | B8: ='👤 Cliente'!B4
A9: Data: | B9: ='👤 Cliente'!E7
A10: Endereço: | B10: ='👤 Cliente'!B10
A11: Consultor: | B11: ='👤 Cliente'!B5
A12: Contato: | B12: ='👤 Cliente'!E6
A14: 🗺️ MAPA ENERGÉTICO — Colorido Automaticamente
A15: Prosperidade | C15: Fama | E15: Relacionamentos
A16: ='📊 Score Energético'!F11 | C16: ='📊 Score Energético'!F12 | E16: ='📊 Score Energético'!F13
A17: Família | C17: Saúde | E17: Criatividade
A18: ='📊 Score Energético'!F14 | C18: ='📊 Score Energético'!F15 | E18: ='📊 Score Energético'!F16
A19: Conhecimento | C19: Carreira | E19: Ajudantes
A20: ='📊 Score Energético'!F17 | C20: ='📊 Score Energético'!F18 | E20: ='📊 Score Energético'!F19
A22: 🚪 Porta de entrada:
A24: 📊 DIAGNÓSTICO AUTOMÁTICO POR SETOR
A25: Setor | B25: Score | C25: % Saúde | D25: Status 🚦 | E25: Ativação Prioritária
A26: 🔴 Prosperidade | B26: ='📊 Score Energético'!D11 | C26: ='📊 Score Energético'!F11 | D26: ='📊 Score Energético'!G11 | E26: Planta robusta + luz p/ cima + objeto dourado no closet
A27: 🔥 Fama | B27: ='📊 Score Energético'!D12 | C27: ='📊 Score Energético'!F12 | D27: ='📊 Score Energético'!G12 | E27: Iluminação forte no teto + obra em tons de fogo + diplomas em molduras
A28: 💜 Relacionamentos | B28: ='📊 Score Energético'!D13 | C28: ='📊 Score Energético'!F13 | D28: ='📊 Score Energético'!G13 | E28: Objetos em pares simétricos + cristal quartzo rosa + luz quente
A29: 🌿 Família | B29: ='📊 Score Energético'!D14 | C29: ='📊 Score Energético'!F14 | D29: ='📊 Score Energético'!G14 | E29: Planta folha larga + foto de família + reorganização profunda
A30: 🟡 Saúde | B30: ='📊 Score Energético'!D15 | C30: ='📊 Score Energético'!F15 | D30: ='📊 Score Energético'!G15 | E30: Tapete natural no corredor + cristal citrino + iluminação equilibrada
A31: ⭕ Criatividade | B31: ='📊 Score Energético'!D16 | C31: ='📊 Score Energético'!F16 | D31: ='📊 Score Energético'!G16 | E31: Flores em vasos + elemento circular no living + fruteira na mesa
A32: 📚 Conhecimento | B32: ='📊 Score Energético'!D17 | C32: ='📊 Score Energético'!F17 | D32: ='📊 Score Energético'!G17 | E32: Cristal azul ou verde + livros organizados + luz suave
A33: 🔵 Carreira | B33: ='📊 Score Energético'!D18 | C33: ='📊 Score Energético'!F18 | D33: ='📊 Score Energético'!G18 | E33: Espelho lateral + tapete de qualidade + iluminação forte na entrada
A34: 🤝 Ajudantes | B34: ='📊 Score Energético'!D19 | C34: ='📊 Score Energético'!F19 | D34: ='📊 Score Energético'!G19 | E34: Elemento metálico + luz na entrada de serviço + organização
A37: ⚠️ LEMBRETES AO CLIENTE
A38: • A INTENÇÃO é mais poderosa que o objeto. Ative sempre com os Três Segredos: Gesto + Mantra + Visualização (9x).
A39: • Manter LIMPO e ORGANIZADO é o pré-requisito de qualquer ativação. Desordem desfaz tudo.
A40: • Plantas doentes devem ser removidas imediatamente — representam energia estagnada.
A41: • Espelhos: NUNCA de frente para a porta de entrada ou refletindo a cama.
A42: • Renove os rituais a cada 9 semanas para manter a energia ativa e crescente.

Sheet ⚙️ Apps Script (PDF)
A1: ⚙️ GOOGLE APPS SCRIPT — 5 Macros Automáticas
A3: 📌 Cole TODO o código abaixo em: Google Sheets → Extensões → Apps Script → Novo projeto → Substituir tudo → Salvar
A4: 📋 ÍNDICE DAS MACROS
A5: 💻 CÓDIGO COMPLETO — Copie tudo abaixo e cole no Apps Script
A6: Como instalar: Google Sheets → Extensões → Apps Script → selecionar tudo → colar → 💾 Salvar → ▶ Executar onOpen
A7: // ================================================================
A8: // FENG SHUI CHAPÉU PRETO — Sistema do Consultor
A9: // Google Apps Script — v3.2
A10: // Cole este código inteiro no editor do Apps Script
A11: // ================================================================
A13: // ── CONFIGURAÇÕES (ajuste conforme necessário) ───────────────
A14: var CONFIG = {
... A435: 🚀 FLUXO DE USO RECOMENDADO — Em cada consulta
A436: ANTES da visita | B436: ▶ Preencher 👤 Cliente → ▶ Validar preenchimento
A437: Durante a visita | B437: ▶ Ba Gua Automático → ▶ Diagnóstico (células azuis)
A438: Após a visita | B438: ▶ Validar preenchimento → ▶ Gerar PDF → ▶ Enviar WhatsApp
A439: Antes de limpar | B439: ▶ Salvar snapshot histórico → ▶ Limpar para nova consulta

Sheet 📅 Cronograma Lunar
A1: 📅 CRONOGRAMA LUNAR DE RITUAIS
A3: O ciclo lunar tem ~29 dias. Alinhe os rituais às fases para potencializar cada ativação.
A5: 🌑 LUA NOVA
A6: Energia: | B6: Energia de plantio e intenção
A7: Ação: | B7: Limpar + Intenção
A8: Rituais: | B8: Limpeza energética geral. Organizar lavanderia (Família). Definir intenções do ciclo.
A10: 🌒 CRESCENTE
A11: Energia: | B11: Expansão — momento de ativar
A12: Ação: | B12: Ativar + Plantar
A13: Rituais: | B13: Posicionar plantas (Prosperidade, Família). Espelhos e tapetes (Carreira). Cristal citrino (Saúde).
A15: 🌕 LUA CHEIA
A16: Energia: | B16: Pico de energia — amor e fama
A17: Ação: | B17: Amplificar + Brilhar
A18: Rituais: | B18: Cristal quartzo rosa (Relacionamentos). Iluminação e obra de arte (Fama). Rituais de pares.
A20: 🌘 MINGUANTE
A21: Energia: | B21: Dissolução — soltar e renovar
A22: Ação: | B22: Soltar + Renovar
A23: Rituais: | B23: Descartar o que não serve. Roupas velhas do closet. Limpar terraço técnico.
A25: 🔄 CICLO DE RENOVAÇÃO — 9 Semanas
A26: Semana | B26: Fase | C26: Setores | E26: Concluído | F26: Data | G26: Observações
A27: Semana 1 | B27: 🌑 Lua Nova | C27: Limpeza Geral + Família | E27: ☐
A28: Semana 2 | B28: 🌒 Crescente | C28: Prosperidade + Carreira | E28: ☐
A29: Semana 3 | B29: 🌒 Crescente | C29: Saúde + Conhecimento | E29: ☐
A30: Semana 4 | B30: 🌕 Cheia | C30: Relacionamentos + Fama | E30: ☐
A31: Semana 5 | B31: 🌘 Minguante | C31: Descarte + Renovação | E31: ☐
A32: Semana 6 | B32: 🌑 Lua Nova | C32: Nova Intenção | E32: ☐
A33: Semana 7 | B33: 🌒 Crescente | C33: Criatividade + Ajudantes | E33: ☐
A34: Semana 8 | B34: 🌕 Cheia | C34: Amplificação Geral | E34: ☐
A35: Semana 9 | B35: 🌘 Minguante | C35: Fechamento + Gratidão | E35: ☐

Sheet 🔐 Senha e Acesso
A1: 🔐 PROTEÇÃO DA PLANILHA
A3: Senha para desproteger: | B3: fengshui2026
A4: Como desproteger: | B4: Planilha → Revisão → Desproteger Planilha → Digite a senha
A5: Células editáveis: | B5: Identificadas por fundo AZUL CLARO no Diagnóstico
A6: Células travadas: | B6: Fórmulas e cabeçalhos — não edite para não quebrar o modelo
A7: Esqueceu a senha? | B7: Entre em contato com o desenvolvedor da planilha
